Workbook

Sheet Dashboard
A1: Recruitment Funnel Dashboard
A2: Talent Acquisition project | Mock data (100 candidates, Jun-Oct 2026) | Replace the blue cells in Candidate_Data with your own anonymised data
A4: Total Applicants | B4: Shortlisted | C4: Interviewed | D4: Offers Made | E4: Joined | F4: Offer Acceptance Rate | G4: Avg Days to Hire | H4: Applicant-to-Join Rate
A5: =B11 -> 100 | B5: =B12 -> 62 | C5: =B13 -> 44 | D5: =B14 -> 20 | E5: =B15 -> 16 | F5: =IF(B14=0,0,B15/B14) -> 0.8 | G5: =IFERROR(AVERAGE(Candidate_Data!$J$2:$J$300),0) -> 27.375 | H5: =IF(B11=0,0,B15/B11) -> 0.16
A9: 1. Hiring Funnel
A10: Stage | B10: Candidates | C10: % of Applicants | D10: Drop-off vs Previous Stage
A11: Applied | B11: =COUNTA(Candidate_Data!$A$2:$A$300) -> 100 | C11: =IF($B$11=0,0,B11/$B$11) -> 1 | D11: -
A12: Shortlisted | B12: =COUNTIF(Candidate_Data!$E$2:$E$300,"Yes") -> 62 | C12: =IF($B$11=0,0,B12/$B$11) -> 0.62 | D12: =IF(B11=0,0,1-B12/B11) -> 0.38
A13: Interviewed | B13: =COUNTIF(Candidate_Data!$F$2:$F$300,"Yes") -> 44 | C13: =IF($B$11=0,0,B13/$B$11) -> 0.44 | D13: =IF(B12=0,0,1-B13/B12) -> 0.29032258
A14: Offer Made | B14: =COUNTIF(Candidate_Data!$G$2:$G$300,"Yes") -> 20 | C14: =IF($B$11=0,0,B14/$B$11) -> 0.2 | D14: =IF(B13=0,0,1-B14/B13) -> 0.54545455
A15: Joined | B15: =COUNTIF(Candidate_Data!$H$2:$H$300,"Yes") -> 16 | C15: =IF($B$11=0,0,B15/$B$11) -> 0.16 | D15: =IF(B14=0,0,1-B15/B14) -> 0.2
A17: 2. Performance by Sourcing Channel
A18: Source | B18: Applicants | C18: Shortlisted | D18: Interviewed | E18: Offers | F18: Joined | G18: Joining Rate | H18: Avg Days to Hire
A19: LinkedIn | B19: =COUNTIF(Candidate_Data!$C$2:$C$300,$A19) -> 32 | C19: =COUNTIFS(Candidate_Data!$C$2:$C$300,$A19,Candidate_Data!$E$2:$E$300,"Yes") -> 20 | D19: =COUNTIFS(Candidate_Data!$C$2:$C$300,$A19,Candidate_Data!$F$2:$F$300,"Yes") -> 14 | E19: =COUNTIFS(Candidate_Data!$C$2:$C$300,$A19,Candidate_Data!$G$2:$G$300,"Yes") -> 6 | F19: =COUNTIFS(Candidate_Data!$C$2:$C$300,$A19,Candidate_Data!$H$2:$H$300,"Yes") -> 4 | G19: =IF(B19=0,0,F19/B19) -> 0.125 | H19: =IFERROR(AVERAGEIFS(Candidate_Data!$J$2:$J$300,Candidate_Data!$C$2:$C$300,$A19),"") -> 34.75
A20: Naukri | B20: =COUNTIF(Candidate_Data!$C$2:$C$300,$A20) -> 24 | C20: =COUNTIFS(Candidate_Data!$C$2:$C$300,$A20,Candidate_Data!$E$2:$E$300,"Yes") -> 12 | D20: =COUNTIFS(Candidate_Data!$C$2:$C$300,$A20,Candidate_Data!$F$2:$F$300,"Yes") -> 8 | E20: =COUNTIFS(Candidate_Data!$C$2:$C$300,$A20,Candidate_Data!$G$2:$G$300,"Yes") -> 4 | F20: =COUNTIFS(Candidate_Data!$C$2:$C$300,$A20,Candidate_Data!$H$2:$H$300,"Yes") -> 2 | G20: =IF(B20=0,0,F20/B20) -> 0.083333333 | H20: =IFERROR(AVERAGEIFS(Candidate_Data!$J$2:$J$300,Candidate_Data!$C$2:$C$300,$A20),"") -> 32
A21: Indeed | B21: =COUNTIF(Candidate_Data!$C$2:$C$300,$A21) -> 16 | C21: =COUNTIFS(Candidate_Data!$C$2:$C$300,$A21,Candidate_Data!$E$2:$E$300,"Yes") -> 8 | D21: =COUNTIFS(Candidate_Data!$C$2:$C$300,$A21,Candidate_Data!$F$2:$F$300,"Yes") -> 7 | E21: =COUNTIFS(Candidate_Data!$C$2:$C$300,$A21,Candidate_Data!$G$2:$G$300,"Yes") -> 3 | F21: =COUNTIFS(Candidate_Data!$C$2:$C$300,$A21,Candidate_Data!$H$2:$H$300,"Yes") -> 3 | G21: =IF(B21=0,0,F21/B21) -> 0.1875 | H21: =IFERROR(AVERAGEIFS(Candidate_Data!$J$2:$J$300,Candidate_Data!$C$2:$C$300,$A21),"") -> 35
A22: Employee Referral | B22: =COUNTIF(Candidate_Data!$C$2:$C$300,$A22) -> 14 | C22: =COUNTIFS(Candidate_Data!$C$2:$C$300,$A22,Candidate_Data!$E$2:$E$300,"Yes") -> 12 | D22: =COUNTIFS(Candidate_Data!$C$2:$C$300,$A22,Candidate_Data!$F$2:$F$300,"Yes") -> 9 | E22: =COUNTIFS(Candidate_Data!$C$2:$C$300,$A22,Candidate_Data!$G$2:$G$300,"Yes") -> 6 | F22: =COUNTIFS(Candidate_Data!$C$2:$C$300,$A22,Candidate_Data!$H$2:$H$300,"Yes") -> 6 | G22: =IF(B22=0,0,F22/B22) -> 0.42857143 | H22: =IFERROR(AVERAGEIFS(Candidate_Data!$J$2:$J$300,Candidate_Data!$C$2:$C$300,$A22),"") -> 17.166667
A23: Campus | B23: =COUNTIF(Candidate_Data!$C$2:$C$300,$A23) -> 14 | C23: =COUNTIFS(Candidate_Data!$C$2:$C$300,$A23,Candidate_Data!$E$2:$E$300,"Yes") -> 10 | D23: =COUNTIFS(Candidate_Data!$C$2:$C$300,$A23,Candidate_Data!$F$2:$F$300,"Yes") -> 6 | E23: =COUNTIFS(Candidate_Data!$C$2:$C$300,$A23,Candidate_Data!$G$2:$G$300,"Yes") -> 1 | F23: =COUNTIFS(Candidate_Data!$C$2:$C$300,$A23,Candidate_Data!$H$2:$H$300,"Yes") -> 1 | G23: =IF(B23=0,0,F23/B23) -> 0.071428571 | H23: =IFERROR(AVERAGEIFS(Candidate_Data!$J$2:$J$300,Candidate_Data!$C$2:$C$300,$A23),"") -> 27
A24: Total | B24: =SUM(B19:B23) -> 100 | C24: =SUM(C19:C23) -> 62 | D24: =SUM(D19:D23) -> 44 | E24: =SUM(E19:E23) -> 20 | F24: =SUM(F19:F23) -> 16 | G24: =IF(B24=0,0,F24/B24) -> 0.16 | H24: =IFERROR(AVERAGE(Candidate_Data!$J$2:$J$300),"") -> 27.375
A26: 3. Performance by Role
A27: Role | B27: Applicants | C27: Shortlisted | D27: Interviewed | E27: Offers | F27: Joined | G27: Joining Rate | H27: Avg Days to Hire
A28: Sales Executive | B28: =COUNTIF(Candidate_Data!$B$2:$B$300,$A28) -> 32 | C28: =COUNTIFS(Candidate_Data!$B$2:$B$300,$A28,Candidate_Data!$E$2:$E$300,"Yes") -> 23 | D28: =COUNTIFS(Candidate_Data!$B$2:$B$300,$A28,Candidate_Data!$F$2:$F$300,"Yes") -> 18 | E28: =COUNTIFS(Candidate_Data!$B$2:$B$300,$A28,Candidate_Data!$G$2:$G$300,"Yes") -> 11 | F28: =COUNTIFS(Candidate_Data!$B$2:$B$300,$A28,Candidate_Data!$H$2:$H$300,"Yes") -> 8 | G28: =IF(B28=0,0,F28/B28) -> 0.25 | H28: =IFERROR(AVERAGEIFS(Candidate_Data!$J$2:$J$300,Candidate_Data!$B$2:$B$300,$A28),"") -> 30.75
A29: HR Executive | B29: =COUNTIF(Candidate_Data!$B$2:$B$300,$A29) -> 15 | C29: =COUNTIFS(Candidate_Data!$B$2:$B$300,$A29,Candidate_Data!$E$2:$E$300,"Yes") -> 9 | D29: =COUNTIFS(Candidate_Data!$B$2:$B$300,$A29,Candidate_Data!$F$2:$F$300,"Yes") -> 9 | E29: =COUNTIFS(Candidate_Data!$B$2:$B$300,$A29,Candidate_Data!$G$2:$G$300,"Yes") -> 2 | F29: =COUNTIFS(Candidate_Data!$B$2:$B$300,$A29,Candidate_Data!$H$2:$H$300,"Yes") -> 2 | G29: =IF(B29=0,0,F29/B29) -> 0.13333333 | H29: =IFERROR(AVERAGEIFS(Candidate_Data!$J$2:$J$300,Candidate_Data!$B$2:$B$300,$A29),"") -> 21.5
A30: Customer Support Executive | B30: =COUNTIF(Candidate_Data!$B$2:$B$300,$A30) -> 32 | C30: =COUNTIFS(Candidate_Data!$B$2:$B$300,$A30,Candidate_Data!$E$2:$E$300,"Yes") -> 17 | D30: =COUNTIFS(Candidate_Data!$B$2:$B$300,$A30,Candidate_Data!$F$2:$F$300,"Yes") -> 11 | E30: =COUNTIFS(Candidate_Data!$B$2:$B$300,$A30,Candidate_Data!$G$2:$G$300,"Yes") -> 6 | F30: =COUNTIFS(Candidate_Data!$B$2:$B$300,$A30,Candidate_Data!$H$2:$H$300,"Yes") -> 5 | G30: =IF(B30=0,0,F30/B30) -> 0.15625 | H30: =IFERROR(AVERAGEIFS(Candidate_Data!$J$2:$J$300,Candidate_Data!$B$2:$B$300,$A30),"") -> 25
A31: Digital Marketing Executive | B31: =COUNTIF(Candidate_Data!$B$2:$B$300,$A31) -> 21 | C31: =COUNTIFS(Candidate_Data!$B$2:$B$300,$A31,Candidate_Data!$E$2:$E$300,"Yes") -> 13 | D31: =COUNTIFS(Candidate_Data!$B$2:$B$300,$A31,Candidate_Data!$F$2:$F$300,"Yes") -> 6 | E31: =COUNTIFS(Candidate_Data!$B$2:$B$300,$A31,Candidate_Data!$G$2:$G$300,"Yes") -> 1 | F31: =COUNTIFS(Candidate_Data!$B$2:$B$300,$A31,Candidate_Data!$H$2:$H$300,"Yes") -> 1 | G31: =IF(B31=0,0,F31/B31) -> 0.047619048 | H31: =IFERROR(AVERAGEIFS(Candidate_Data!$J$2:$J$300,Candidate_Data!$B$2:$B$300,$A31),"") -> 24
A32: Total | B32: =SUM(B28:B31) -> 100 | C32: =SUM(C28:C31) -> 62 | D32: =SUM(D28:D31) -> 44 | E32: =SUM(E28:E31) -> 20 | F32: =SUM(F28:F31) -> 16 | G32: =IF(B32=0,0,F32/B32) -> 0.16 | H32: =IFERROR(AVERAGE(Candidate_Data!$J$2:$J$300),"") -> 27.375
A34: 4. Key Insights (update automatically)
A35: ="Best-converting source: "&INDEX($A$19:$A$23,MATCH(MAX($G$19:$G$23),$G$19:$G$23,0))&" - "&TEXT(MAX($G$19:$G$23),"0%")&" of its applicants joined." -> Best-converting source: Employee Referral - 43% of its applicants joined.
A36: ="Highest-volume source: "&INDEX($A$19:$A$23,MATCH(MAX($B$19:$B$23),$B$19:$B$23,0))&" with "&MAX($B$19:$B$23)&" applicants, but only "&TEXT(INDEX($G$19:$G$23,MATCH(MAX($B$19:$B$23),$B$19:$B$23,0)),"0%")&" joined." -> Highest-volume source: LinkedIn with 32 applicants, but only 13% joined.
A37: ="Fastest source to hire: "&INDEX($A$19:$A$23,MATCH(MIN($H$19:$H$23),$H$19:$H$23,0))&" at "&TEXT(MIN($H$19:$H$23),"0.0")&" days on average vs "&TEXT($H$24,"0.0")&" overall." -> Fastest source to hire: Employee Referral at 17.2 days on average vs 27.4 overall.
A38: ="Biggest funnel drop-off: at the "&INDEX($A$12:$A$15,MATCH(MAX($D$12:$D$15),$D$12:$D$15,0))&" stage ("&TEXT(MAX($D$12:$D$15),"0%")&" of candidates lost from the previous stage)." -> Biggest funnel drop-off: at the Offer Made stage (55% of candidates lost from the previous stage).
A39: ="Offer acceptance rate is "&TEXT($F$5,"0%")&" - "&($B$14-$B$15)&" offers did not convert into joinings." -> Offer acceptance rate is 80% - 4 offers did not convert into joinings.
A41: Recommendation: put more recruiter effort into the best-converting channel and fix the stage with the biggest drop-off (edit this line after reviewing your own data).

Sheet Candidate_Data
A1: Candidate ID | B1: Role | C1: Source | D1: Application Date | E1: Shortlisted | F1: Interviewed | G1: Offer Made | H1: Joined | I1: Joining Date | J1: Days to Hire | K1: Final Status
A2: CAND-001 | B2: Digital Marketing Executive | C2: LinkedIn | D2: 46176 | E2: Yes | F2: No | G2: No | H2: No | J2: =IF(A2="","",IF(AND(H2="Yes",I2<>""),I2-D2,"")) | K2: =IF(A2="","",IF(H2="Yes","Joined",IF(G2="Yes","Offer Declined",IF(F2="Yes","Rejected after Interview",IF(E2="Yes","Not Selected for Interview","Rejected at Screening"))))) -> Not Selected for Interview
A3: CAND-002 | B3: Customer Support Executive | C3: Naukri | D3: 46177 | E3: Yes | F3: No | G3: No | H3: No | J3: =IF(A3="","",IF(AND(H3="Yes",I3<>""),I3-D3,"")) | K3: =IF(A3="","",IF(H3="Yes","Joined",IF(G3="Yes","Offer Declined",IF(F3="Yes","Rejected after Interview",IF(E3="Yes","Not Selected for Interview","Rejected at Screening"))))) -> Not Selected for Interview
A4: CAND-003 | B4: Customer Support Executive | C4: Naukri | D4: 46177 | E4: No | F4: No | G4: No | H4: No | J4: =IF(A4="","",IF(AND(H4="Yes",I4<>""),I4-D4,"")) | K4: =IF(A4="","",IF(H4="Yes","Joined",IF(G4="Yes","Offer Declined",IF(F4="Yes","Rejected after Interview",IF(E4="Yes","Not Selected for Interview","Rejected at Screening"))))) -> Rejected at Screening
A5: CAND-004 | B5: HR Executive | C5: LinkedIn | D5: 46180 | E5: No | F5: No | G5: No | H5: No | J5: =IF(A5="","",IF(AND(H5="Yes",I5<>""),I5-D5,"")) | K5: =IF(A5="","",IF(H5="Yes","Joined",IF(G5="Yes","Offer Declined",IF(F5="Yes","Rejected after Interview",IF(E5="Yes","Not Selected for Interview","Rejected at Screening"))))) -> Rejected at Screening
A6: CAND-005 | B6: Digital Marketing Executive | C6: Campus | D6: 46180 | E6: Yes | F6: No | G6: No | H6: No | J6: =IF(A6="","",IF(AND(H6="Yes",I6<>""),I6-D6,"")) | K6: =IF(A6="","",IF(H6="Yes","Joined",IF(G6="Yes","Offer Declined",IF(F6="Yes","Rejected after Interview",IF(E6="Yes","Not Selected for Interview","Rejected at Screening"))))) -> Not Selected for Interview
A7: CAND-006 | B7: Sales Executive | C7: LinkedIn | D7: 46181 | E7: Yes | F7: Yes | G7: Yes | H7: Yes | I7: 46217 | J7: =IF(A7="","",IF(AND(H7="Yes",I7<>""),I7-D7,"")) -> 36 | K7: =IF(A7="","",IF(H7="Yes","Joined",IF(G7="Yes","Offer Declined",IF(F7="Yes","Rejected after Interview",IF(E7="Yes","Not Selected for Interview","Rejected at Screening"))))) -> Joined
A8: CAND-007 | B8: Digital Marketing Executive | C8: LinkedIn | D8: 46182 | E8: Yes | F8: Yes | G8: No | H8: No | J8: =IF(A8="","",IF(AND(H8="Yes",I8<>""),I8-D8,"")) | K8: =IF(A8="","",IF(H8="Yes","Joined",IF(G8="Yes","Offer Declined",IF(F8="Yes","Rejected after Interview",IF(E8="Yes","Not Selected for Interview","Rejected at Screening"))))) -> Rejected after Interview
A9: CAND-008 | B9: Digital Marketing Executive | C9: LinkedIn | D9: 46183 | E9: Yes | F9: Yes | G9: No | H9: No | J9: =IF(A9="","",IF(AND(H9="Yes",I9<>""),I9-D9,"")) | K9: =IF(A9="","",IF(H9="Yes","Joined",IF(G9="Yes","Offer Declined",IF(F9="Yes","Rejected after Interview",IF(E9="Yes","Not Selected for Interview","Rejected at Screening"))))) -> Rejected after Interview
A10: CAND-009 | B10: Customer Support Executive | C10: Naukri | D10: 46184 | E10: No | F10: No | G10: No | H10: No | J10: =IF(A10="","",IF(AND(H10="Yes",I10<>""),I10-D10,"")) | K10: =IF(A10="","",IF(H10="Yes","Joined",IF(G10="Yes","Offer Declined",IF(F10="Yes","Rejected after Interview",IF(E10="Yes","Not Selected for Interview","Rejected at Screening"))))) -> Rejected at Screening
A11: CAND-010 | B11: Digital Marketing Executive | C11: Naukri | D11: 46185 | E11: Yes | F11: No | G11: No | H11: No | J11: =IF(A11="","",IF(AND(H11="Yes",I11<>""),I11-D11,"")) | K11: =IF(A11="","",IF(H11="Yes","Joined",IF(G11="Yes","Offer Declined",IF(F11="Yes","Rejected after Interview",IF(E11="Yes","Not Selected for Interview","Rejected at Screening"))))) -> Not Selected for Interview
A12: CAND-011 | B12: Customer Support Executive | C12: Naukri | D12: 46185 | E12: Yes | F12: No | G12: No | H12: No | J12: =IF(A12="","",IF(AND(H12="Yes",I12<>""),I12-D12,"")) | K12: =IF(A12="","",IF(H12="Yes","Joined",IF(G12="Yes","Offer Declined",IF(F12="Yes","Rejected after Interview",IF(E12="Yes","Not Selected for Interview","Rejected at Screening"))))) -> Not Selected for Interview
A13: CAND-012 | B13: HR Executive | C13: Employee Referral | D13: 46186 | E13: Yes | F13: Yes | G13: No | H13: No | J13: =IF(A13="","",IF(AND(H13="Yes",I13<>""),I13-D13,"")) | K13: =IF(A13="","",IF(H13="Yes","Joined",IF(G13="Yes","Offer Declined",IF(F13="Yes","Rejected after Interview",IF(E13="Yes","Not Selected for Interview","Rejected at Screening"))))) -> Rejected after Interview
A14: CAND-013 | B14: Sales Executive | C14: Naukri | D14: 46186 | E14: Yes | F14: Yes | G14: Yes | H14: Yes | I14: 46223 | J14: =IF(A14="","",IF(AND(H14="Yes",I14<>""),I14-D14,"")) -> 37 | K14: =IF(A14="","",IF(H14="Yes","Joined",IF(G14="Yes","Offer Declined",IF(F14="Yes","Rejected after Interview",IF(E14="Yes","Not Selected for Interview","Rejected at Screening"))))) -> Joined
A15: CAND-014 | B15: Customer Support Executive | C15: Campus | D15: 46187 | E15: No | F15: No | G15: No | H15: No | J15: =IF(A15="","",IF(AND(H15="Yes",I15<>""),I15-D15,"")) | K15: =IF(A15="","",IF(H15="Yes","Joined",IF(G15="Yes","Offer Declined",IF(F15="Yes","Rejected after Interview",IF(E15="Yes","Not Selected for Interview","Rejected at Screening"))))) -> Rejected at Screening
A16: CAND-015 | B16: Digital Marketing Executive | C16: Indeed | D16: 46187 | E16: Yes | F16: Yes | G16: No | H16: No | J16: =IF(A16="","",IF(AND(H16="Yes",I16<>""),I16-D16,"")) | K16: =IF(A16="","",IF(H16="Yes","Joined",IF(G16="Yes","Offer Declined",IF(F16="Yes","Rejected after Interview",IF(E16="Yes","Not Selected for Interview","Rejected at Screening"))))) -> Rejected after Interview
A17: CAND-016 | B17: Digital Marketing Executive | C17: Campus | D17: 46188 | E17: Yes | F17: No | G17: No | H17: No | J17: =IF(A17="","",IF(AND(H17="Yes",I17<>""),I17-D17,"")) | K17: =IF(A17="","",IF(H17="Yes","Joined",IF(G17="Yes","Offer Declined",IF(F17="Yes","Rejected after Interview",IF(E17="Yes","Not Selected for Interview","Rejected at Screening"))))) -> Not Selected for Interview
A18: CAND-017 | B18: Customer Support Executive | C18: Indeed | D18: 46189 | E18: No | F18: No | G18: No | H18: No | J18: =IF(A18="","",IF(AND(H18="Yes",I18<>""),I18-D18,"")) | K18: =IF(A18="","",IF(H18="Yes","Joined",IF(G18="Yes","Offer Declined",IF(F18="Yes","Rejected after Interview",IF(E18="Yes","Not Selected for Interview","Rejected at Screening"))))) -> Rejected at Screening
A19: CAND-018 | B19: Customer Support Executive | C19: Employee Referral | D19: 46189 | E19: Yes | F19: Yes | G19: Yes | H19: Yes | I19: 46203 | J19: =IF(A19="","",IF(AND(H19="Yes",I19<>""),I19-D19,"")) -> 14 | K19: =IF(A19="","",IF(H19="Yes","Joined",IF(G19="Yes","Offer Declined",IF(F19="Yes","Rejected after Interview",IF(E19="Yes","Not Selected for Interview","Rejected at Screening"))))) -> Joined
A20: CAND-019 | B20: Customer Support Executive | C20: LinkedIn | D20: 46189 | E20: Yes | F20: No | G20: No | H20: No | J20: =IF(A20="","",IF(AND(H20="Yes",I20<>""),I20-D20,"")) | K20: =IF(A20="","",IF(H20="Yes","Joined",IF(G20="Yes","Offer Declined",IF(F20="Yes","Rejected after Interview",IF(E20="Yes","Not Selected for Interview","Rejected at Screening"))))) -> Not Selected for Interview
A21: CAND-020 | B21: Customer Support Executive | C21: LinkedIn | D21: 46190 | E21: No | F21: No | G21: No | H21: No | J21: =IF(A21="","",IF(AND(H21="Yes",I21<>""),I21-D21,"")) | K21: =IF(A21="","",IF(H21="Yes","Joined",IF(G21="Yes","Offer Declined",IF(F21="Yes","Rejected after Interview",IF(E21="Yes","Not Selected for Interview","Rejected at Screening"))))) -> Rejected at Screening
A22: CAND-021 | B22: Sales Executive | C22: Indeed | D22: 46190 | E22: No | F22: No | G22: No | H22: No | J22: =IF(A22="","",IF(AND(H22="Yes",I22<>""),I22-D22,"")) | K22: =IF(A22="","",IF(H22="Yes","Joined",IF(G22="Yes","Offer Declined",IF(F22="Yes","Rejected after Interview",IF(E22="Yes","Not Selected for Interview","Rejected at Screening"))))) -> Rejected at Screening
A23: CAND-022 | B23: Sales Executive | C23: LinkedIn | D23: 46191 | E23: Yes | F23: Yes | G23: No | H23: No | J23: =IF(A23="","",IF(AND(H23="Yes",I23<>""),I23-D23,"")) | K23: =IF(A23="","",IF(H23="Yes","Joined",IF(G23="Yes","Offer Declined",IF(F23="Yes","Rejected after Interview",IF(E23="Yes","Not Selected for Interview","Rejected at Screening"))))) -> Rejected after Interview
A24: CAND-023 | B24: Sales Executive | C24: Indeed | D24: 46193 | E24: No | F24: No | G24: No | H24: No | J24: =IF(A24="","",IF(AND(H24="Yes",I24<>""),I24-D24,"")) | K24: =IF(A24="","",IF(H24="Yes","Joined",IF(G24="Yes","Offer Declined",IF(F24="Yes","Rejected after Interview",IF(E24="Yes","Not Selected for Interview","Rejected at Screening"))))) -> Rejected at Screening
A25: CAND-024 | B25: Sales Executive | C25: Campus | D25: 46194 | E25: Yes | F25: Yes | G25: Yes | H25: Yes | I25: 46221 | J25: =IF(A25="","",IF(AND(H25="Yes",I25<>""),I25-D25,"")) -> 27 | K25: =IF(A25="","",IF(H25="Yes","Joined",IF(G25="Yes","Offer Declined",IF(F25="Yes","Rejected after Interview",IF(E25="Yes","Not Selected for Interview","Rejected at Screening"))))) -> Joined
A26: CAND-025 | B26: HR Executive | C26: Employee Referral | D26: 46197 | E26: Yes | F26: Yes | G26: No | H26: No | J26: =IF(A26="","",IF(AND(H26="Yes",I26<>""),I26-D26,"")) | K26: =IF(A26="","",IF(H26="Yes","Joined",IF(G26="Yes","Offer Declined",IF(F26="Yes","Rejected after Interview",IF(E26="Yes","Not Selected for Interview","Rejected at Screening"))))) -> Rejected after Interview
A27: CAND-026 | B27: Sales Executive | C27: LinkedIn | D27: 46197 | E27: Yes | F27: Yes | G27: Yes | H27: No | J27: =IF(A27="","",IF(AND(H27="Yes",I27<>""),I27-D27,"")) | K27: =IF(A27="","",IF(H27="Yes","Joined",IF(G27="Yes","Offer Declined",IF(F27="Yes","Rejected after Interview",IF(E27="Yes","Not Selected for Interview","Rejected at Screening"))))) -> Offer Declined
A28: CAND-027 | B28: Customer Support Executive | C28: Indeed | D28: 46197 | E28: Yes | F28: Yes | G28: No | H28: No | J28: =IF(A28="","",IF(AND(H28="Yes",I28<>""),I28-D28,"")) | K28: =IF(A28="","",IF(H28="Yes","Joined",IF(G28="Yes","Offer Declined",IF(F28="Yes","Rejected after Interview",IF(E28="Yes","Not Selected for Interview","Rejected at Screening"))))) -> Rejected after Interview
A29: CAND-028 | B29: HR Executive | C29: LinkedIn | D29: 46198 | E29: No | F29: No | G29: No | H29: No | J29: =IF(A29="","",IF(AND(H29="Yes",I29<>""),I29-D29,"")) | K29: =IF(A29="","",IF(H29="Yes","Joined",IF(G29="Yes","Offer Declined",IF(F29="Yes","Rejected after Interview",IF(E29="Yes","Not Selected for Interview","Rejected at Screening"))))) -> Rejected at Screening
A30: CAND-029 | B30: Digital Marketing Executive | C30: Indeed | D30: 46198 | E30: No | F30: No | G30: No | H30: No | J30: =IF(A30="","",IF(AND(H30="Yes",I30<>""),I30-D30,"")) | K30: =IF(A30="","",IF(H30="Yes","Joined",IF(G30="Yes","Offer Declined",IF(F30="Yes","Rejected after Interview",IF(E30="Yes","Not Selected for Interview","Rejected at Screening"))))) -> Rejected at Screening
A31: CAND-030 | B31: Digital Marketing Executive | C31: Naukri | D31: 46198 | E31: No | F31: No | G31: No | H31: No | J31: =IF(A31="","",IF(AND(H31="Yes",I31<>""),I31-D31,"")) | K31: =IF(A31="","",IF(H31="Yes","Joined",IF(G31="Yes","Offer Declined",IF(F31="Yes","Rejected after Interview",IF(E31="Yes","Not Selected for Interview","Rejected at Screening"))))) -> Rejected at Screening
A32: CAND-031 | B32: Digital Marketing Executive | C32: Employee Referral | D32: 46199 | E32: No | F32: No | G32: No | H32: No | J32: =IF(A32="","",IF(AND(H32="Yes",I32<>""),I32-D32,"")) | K32: =IF(A32="","",IF(H32="Yes","Joined",IF(G32="Yes","Offer Declined",IF(F32="Yes","Rejected after Interview",IF(E32="Yes","Not Selected for Interview","Rejected at Screening"))))) -> Rejected at Screening
A33: CAND-032 | B33: HR Executive | C33: Naukri | D33: 46200 | E33: Yes | F33: Yes | G33: Yes | H33: Yes | I33: 46227 | J33: =IF(A33="","",IF(AND(H33="Yes",I33<>""),I33-D33,"")) -> 27 | K33: =IF(A33="","",IF(H33="Yes","Joined",IF(G33="Yes","Offer Declined",IF(F33="Yes","Rejected after Interview",IF(E33="Yes","Not Selected for Interview","Rejected at Screening"))))) -> Joined
A34: CAND-033 | B34: Sales Executive | C34: LinkedIn | D34: 46201 | E34: Yes | F34: Yes | G34: No | H34: No | J34: =IF(A34="","",IF(AND(H34="Yes",I34<>""),I34-D34,"")) | K34: =IF(A34="","",IF(H34="Yes","Joined",IF(G34="Yes","Offer Declined",IF(F34="Yes","Rejected after Interview",IF(E34="Yes","Not Selected for Interview","Rejected at Screening"))))) -> Rejected after Interview
A35: CAND-034 | B35: Sales Executive | C35: Employee Referral | D35: 46202 | E35: Yes | F35: No | G35: No | H35: No | J35: =IF(A35="","",IF(AND(H35="Yes",I35<>""),I35-D35,"")) | K35: =IF(A35="","",IF(H35="Yes","Joined",IF(G35="Yes","Offer Declined",IF(F35="Yes","Rejected after Interview",IF(E35="Yes","Not Selected for Interview","Rejected at Screening"))))) -> Not Selected for Interview
A36: CAND-035 | B36: Sales Executive | C36: Naukri | D36: 46203 | E36: No | F36: No | G36: No | H36: No | J36: =IF(A36="","",IF(AND(H36="Yes",I36<>""),I36-D36,"")) | K36: =IF(A36="","",IF(H36="Yes","Joined",IF(G36="Yes","Offer Declined",IF(F36="Yes","Rejected after Interview",IF(E36="Yes","Not Selected for Interview","Rejected at Screening"))))) -> Rejected at Screening
A37: CAND-036 | B37: Sales Executive | C37: LinkedIn | D37: 46203 | E37: Yes | F37: Yes | G37: Yes | H37: No | J37: =IF(A37="","",IF(AND(H37="Yes",I37<>""),I37-D37,"")) | K37: =IF(A37="","",IF(H37="Yes","Joined",IF(G37="Yes","Offer Declined",IF(F37="Yes","Rejected after Interview",IF(E37="Yes","Not Selected for Interview","Rejected at Screening"))))) -> Offer Declined
A38: CAND-037 | B38: Sales Executive | C38: Campus | D38: 46203 | E38: Yes | F38: Yes | G38: No | H38: No | J38: =IF(A38="","",IF(AND(H38="Yes",I38<>""),I38-D38,"")) | K38: =IF(A38="","",IF(H38="Yes","Joined",IF(G38="Yes","Offer Declined",IF(F38="Yes","Rejected after Interview",IF(E38="Yes","Not Selected for Interview","Rejected at Screening"))))) -> Rejected after Interview
A39: CAND-038 | B39: Digital Marketing Executive | C39: Employee Referral | D39: 46203 | E39: Yes | F39: No | G39: No | H39: No | J39: =IF(A39="","",IF(AND(H39="Yes",I39<>""),I39-D39,"")) | K39: =IF(A39="","",IF(H39="Yes","Joined",IF(G39="Yes","Offer Declined",IF(F39="Yes","Rejected after Interview",IF(E39="Yes","Not Selected for Interview","Rejected at Screening"))))) -> Not Selected for Interview
A40: CAND-039 | B40: HR Executive | C40: Employee Referral | D40: 46204 | E40: Yes | F40: Yes | G40: Yes | H40: Yes | I40: 46220 | J40: =IF(A40="","",IF(AND(H40="Yes",I40<>""),I40-D40,"")) -> 16 | K40: =IF(A40="","",IF(H40="Yes","Joined",IF(G40="Yes","Offer Declined",IF(F40="Yes","Rejected after Interview",IF(E40="Yes","Not Selected for Interview","Rejected at Screening"))))) -> Joined
...

Sheet ReadMe
A1: Recruitment Funnel Dashboard - How to use
A3: Purpose
A4: Tracks candidates through the hiring funnel (Applied > Shortlisted > Interviewed > Offer > Joined) and shows which sourcing channels and roles convert best.
A6: Sheets
A7: Dashboard - KPIs, funnel, source and role tables, charts and auto-updating insights. Do not type here; it is all formulas.
A8: Candidate_Data - one row per candidate. This is the only sheet you edit.
A10: Colour legend
A11: Blue text = input you can change (Role, Source, dates, Yes/No stages).
A12: Black text = formula. Do not overwrite (Days to Hire, Final Status, everything on the Dashboard).
A14: To use your own data
A15: 1. In Candidate_Data, replace the blue cells with your own ANONYMISED data (use IDs like CAND-001, never real names or phone numbers).
A16: 2. Enter Yes or No for Shortlisted, Interviewed, Offer Made and Joined (dropdowns are provided). A candidate marked Joined should also be marked Yes in every earlier stage.
... A26: COUNTIF / COUNTIFS, AVERAGEIFS, INDEX-MATCH, data validation, conditional summaries, charts, KPI dashboard design.
